[2025-09-18T04:29:10.306+0000] {taskinstance.py:1957} INFO - Dependencies all met for dep_context=non-requeueable deps ti=<TaskInstance: batch_ingestion_dag.validate_data manual__2025-09-18T04:29:04.296968+00:00 [queued]>
[2025-09-18T04:29:10.312+0000] {taskinstance.py:1957} INFO - Dependencies all met for dep_context=requeueable deps ti=<TaskInstance: batch_ingestion_dag.validate_data manual__2025-09-18T04:29:04.296968+00:00 [queued]>
[2025-09-18T04:29:10.312+0000] {taskinstance.py:2171} INFO - Starting attempt 1 of 2
[2025-09-18T04:29:10.321+0000] {taskinstance.py:2192} INFO - Executing <Task(PythonOperator): validate_data> on 2025-09-18 04:29:04.296968+00:00
[2025-09-18T04:29:10.327+0000] {standard_task_runner.py:60} INFO - Started process 225 to run task
[2025-09-18T04:29:10.330+0000] {standard_task_runner.py:87} INFO - Running: ['***', 'tasks', 'run', 'batch_ingestion_dag', 'validate_data', 'manual__2025-09-18T04:29:04.296968+00:00', '--job-id', '3', '--raw', '--subdir', 'DAGS_FOLDER/batch_ingestion_dag.py', '--cfg-path', '/tmp/tmp6s6n2bm4']
[2025-09-18T04:29:10.332+0000] {standard_task_runner.py:88} INFO - Job 3: Subtask validate_data
[2025-09-18T04:29:10.373+0000] {task_command.py:423} INFO - Running <TaskInstance: batch_ingestion_dag.validate_data manual__2025-09-18T04:29:04.296968+00:00 [running]> on host b9864b12bd2e
[2025-09-18T04:29:10.435+0000] {taskinstance.py:2481} INFO - Exporting env vars: AIRFLOW_CTX_DAG_OWNER='***' AIRFLOW_CTX_DAG_ID='batch_ingestion_dag' AIRFLOW_CTX_TASK_ID='validate_data' AIRFLOW_CTX_EXECUTION_DATE='2025-09-18T04:29:04.296968+00:00' AIRFLOW_CTX_TRY_NUMBER='1' AIRFLOW_CTX_DAG_RUN_ID='manual__2025-09-18T04:29:04.296968+00:00'
[2025-09-18T04:29:10.436+0000] {taskinstance.py:2699} ERROR - Task failed with exception
Traceback (most recent call last):
  File "/home/airflow/.local/lib/python3.9/site-packages/airflow/models/taskinstance.py", line 433, in _execute_task
    result = execute_callable(context=context, **execute_callable_kwargs)
  File "/home/airflow/.local/lib/python3.9/site-packages/airflow/operators/python.py", line 199, in execute
    return_value = self.execute_callable()
  File "/home/airflow/.local/lib/python3.9/site-packages/airflow/operators/python.py", line 216, in execute_callable
    return self.python_callable(*self.op_args, **self.op_kwargs)
  File "/opt/airflow/dags/batch_ingestion_dag.py", line 49, in validate_data_with_ge
    from great_expectations.dataset import PandasDataset
ModuleNotFoundError: No module named 'great_expectations.dataset'
[2025-09-18T04:29:10.446+0000] {taskinstance.py:1138} INFO - Marking task as UP_FOR_RETRY. dag_id=batch_ingestion_dag, task_id=validate_data, execution_date=20250918T042904, start_date=20250918T042910, end_date=20250918T042910
[2025-09-18T04:29:10.455+0000] {standard_task_runner.py:107} ERROR - Failed to execute job 3 for task validate_data (No module named 'great_expectations.dataset'; 225)
[2025-09-18T04:29:10.502+0000] {local_task_job_runner.py:234} INFO - Task exited with return code 1
[2025-09-18T04:29:10.529+0000] {taskinstance.py:3281} INFO - 0 downstream tasks scheduled from follow-on schedule check
