[2025-09-18T04:34:12.940+0000] {taskinstance.py:1957} INFO - Dependencies all met for dep_context=non-requeueable deps ti=<TaskInstance: batch_ingestion_dag.validate_data manual__2025-09-18T04:29:04.296968+00:00 [queued]>
[2025-09-18T04:34:12.949+0000] {taskinstance.py:1957} INFO - Dependencies all met for dep_context=requeueable deps ti=<TaskInstance: batch_ingestion_dag.validate_data manual__2025-09-18T04:29:04.296968+00:00 [queued]>
[2025-09-18T04:34:12.949+0000] {taskinstance.py:2171} INFO - Starting attempt 2 of 2
[2025-09-18T04:34:12.960+0000] {taskinstance.py:2192} INFO - Executing <Task(PythonOperator): validate_data> on 2025-09-18 04:29:04.296968+00:00
[2025-09-18T04:34:12.967+0000] {standard_task_runner.py:60} INFO - Started process 382 to run task
[2025-09-18T04:34:12.970+0000] {standard_task_runner.py:87} INFO - Running: ['***', 'tasks', 'run', 'batch_ingestion_dag', 'validate_data', 'manual__2025-09-18T04:29:04.296968+00:00', '--job-id', '4', '--raw', '--subdir', 'DAGS_FOLDER/batch_ingestion_dag.py', '--cfg-path', '/tmp/tmp9tocv86u']
[2025-09-18T04:34:12.973+0000] {standard_task_runner.py:88} INFO - Job 4: Subtask validate_data
[2025-09-18T04:34:13.022+0000] {task_command.py:423} INFO - Running <TaskInstance: batch_ingestion_dag.validate_data manual__2025-09-18T04:29:04.296968+00:00 [running]> on host b9864b12bd2e
[2025-09-18T04:34:13.096+0000] {taskinstance.py:2481} INFO - Exporting env vars: AIRFLOW_CTX_DAG_OWNER='***' AIRFLOW_CTX_DAG_ID='batch_ingestion_dag' AIRFLOW_CTX_TASK_ID='validate_data' AIRFLOW_CTX_EXECUTION_DATE='2025-09-18T04:29:04.296968+00:00' AIRFLOW_CTX_TRY_NUMBER='2' AIRFLOW_CTX_DAG_RUN_ID='manual__2025-09-18T04:29:04.296968+00:00'
[2025-09-18T04:34:13.099+0000] {taskinstance.py:2699} ERROR - Task failed with exception
Traceback (most recent call last):
  File "/home/airflow/.local/lib/python3.9/site-packages/airflow/models/taskinstance.py", line 433, in _execute_task
    result = execute_callable(context=context, **execute_callable_kwargs)
  File "/home/airflow/.local/lib/python3.9/site-packages/airflow/operators/python.py", line 199, in execute
    return_value = self.execute_callable()
  File "/home/airflow/.local/lib/python3.9/site-packages/airflow/operators/python.py", line 216, in execute_callable
    return self.python_callable(*self.op_args, **self.op_kwargs)
  File "/opt/airflow/dags/batch_ingestion_dag.py", line 49, in validate_data_with_ge
    from great_expectations.dataset import PandasDataset
ModuleNotFoundError: No module named 'great_expectations.dataset'
[2025-09-18T04:34:13.110+0000] {taskinstance.py:1138} INFO - Marking task as FAILED. dag_id=batch_ingestion_dag, task_id=validate_data, execution_date=20250918T042904, start_date=20250918T043412, end_date=20250918T043413
[2025-09-18T04:34:13.121+0000] {standard_task_runner.py:107} ERROR - Failed to execute job 4 for task validate_data (No module named 'great_expectations.dataset'; 382)
[2025-09-18T04:34:13.142+0000] {local_task_job_runner.py:234} INFO - Task exited with return code 1
[2025-09-18T04:34:13.164+0000] {taskinstance.py:3281} INFO - 0 downstream tasks scheduled from follow-on schedule check
