[2025-09-18T06:32:00.404+0000] {taskinstance.py:1957} INFO - Dependencies all met for dep_context=non-requeueable deps ti=<TaskInstance: batch_ingestion_dag.load_to_postgres manual__2025-09-18T06:26:34.314177+00:00 [queued]>
[2025-09-18T06:32:00.414+0000] {taskinstance.py:1957} INFO - Dependencies all met for dep_context=requeueable deps ti=<TaskInstance: batch_ingestion_dag.load_to_postgres manual__2025-09-18T06:26:34.314177+00:00 [queued]>
[2025-09-18T06:32:00.414+0000] {taskinstance.py:2171} INFO - Starting attempt 2 of 2
[2025-09-18T06:32:00.425+0000] {taskinstance.py:2192} INFO - Executing <Task(PythonOperator): load_to_postgres> on 2025-09-18 06:26:34.314177+00:00
[2025-09-18T06:32:00.431+0000] {standard_task_runner.py:60} INFO - Started process 394 to run task
[2025-09-18T06:32:00.434+0000] {standard_task_runner.py:87} INFO - Running: ['***', 'tasks', 'run', 'batch_ingestion_dag', 'load_to_postgres', 'manual__2025-09-18T06:26:34.314177+00:00', '--job-id', '7', '--raw', '--subdir', 'DAGS_FOLDER/batch_ingestion_dag.py', '--cfg-path', '/tmp/tmppbdgm9sa']
[2025-09-18T06:32:00.437+0000] {standard_task_runner.py:88} INFO - Job 7: Subtask load_to_postgres
[2025-09-18T06:32:00.482+0000] {task_command.py:423} INFO - Running <TaskInstance: batch_ingestion_dag.load_to_postgres manual__2025-09-18T06:26:34.314177+00:00 [running]> on host 3aa26d851e1b
[2025-09-18T06:32:00.547+0000] {taskinstance.py:2481} INFO - Exporting env vars: AIRFLOW_CTX_DAG_OWNER='***' AIRFLOW_CTX_DAG_ID='batch_ingestion_dag' AIRFLOW_CTX_TASK_ID='load_to_postgres' AIRFLOW_CTX_EXECUTION_DATE='2025-09-18T06:26:34.314177+00:00' AIRFLOW_CTX_TRY_NUMBER='2' AIRFLOW_CTX_DAG_RUN_ID='manual__2025-09-18T06:26:34.314177+00:00'
[2025-09-18T06:32:00.548+0000] {batch_ingestion_dag.py:161} INFO - Starting load into Postgres from /tmp/transformed_orders.csv...
[2025-09-18T06:32:00.565+0000] {base.py:83} INFO - Using connection ID 'postgres_default' for task execution.
[2025-09-18T06:32:00.570+0000] {batch_ingestion_dag.py:205} ERROR - Failed to load data into Postgres: connection to server at "postgres" (172.20.0.9), port 5432 failed: FATAL:  password authentication failed for user "postgres"

[2025-09-18T06:32:00.571+0000] {taskinstance.py:2699} ERROR - Task failed with exception
Traceback (most recent call last):
  File "/home/airflow/.local/lib/python3.9/site-packages/airflow/models/taskinstance.py", line 433, in _execute_task
    result = execute_callable(context=context, **execute_callable_kwargs)
  File "/home/airflow/.local/lib/python3.9/site-packages/airflow/operators/python.py", line 199, in execute
    return_value = self.execute_callable()
  File "/home/airflow/.local/lib/python3.9/site-packages/airflow/operators/python.py", line 216, in execute_callable
    return self.python_callable(*self.op_args, **self.op_kwargs)
  File "/opt/airflow/dags/batch_ingestion_dag.py", line 174, in load_to_postgres
    pg_hook.run(
  File "/home/airflow/.local/lib/python3.9/site-packages/airflow/providers/common/sql/hooks/sql.py", line 385, in run
    with closing(self.get_conn()) as conn:
  File "/home/airflow/.local/lib/python3.9/site-packages/airflow/providers/postgres/hooks/postgres.py", line 158, in get_conn
    self.conn = psycopg2.connect(**conn_args)
  File "/home/airflow/.local/lib/python3.9/site-packages/psycopg2/__init__.py", line 122, in connect
    conn = _connect(dsn, connection_factory=connection_factory, **kwasync)
psycopg2.OperationalError: connection to server at "postgres" (172.20.0.9), port 5432 failed: FATAL:  password authentication failed for user "postgres"

[2025-09-18T06:32:00.580+0000] {taskinstance.py:1138} INFO - Marking task as FAILED. dag_id=batch_ingestion_dag, task_id=load_to_postgres, execution_date=20250918T062634, start_date=20250918T063200, end_date=20250918T063200
[2025-09-18T06:32:00.590+0000] {standard_task_runner.py:107} ERROR - Failed to execute job 7 for task load_to_postgres (connection to server at "postgres" (172.20.0.9), port 5432 failed: FATAL:  password authentication failed for user "postgres"
; 394)
[2025-09-18T06:32:00.606+0000] {local_task_job_runner.py:234} INFO - Task exited with return code 1
[2025-09-18T06:32:00.624+0000] {taskinstance.py:3281} INFO - 0 downstream tasks scheduled from follow-on schedule check
