[2025-09-18T04:17:59.442+0000] {taskinstance.py:1957} INFO - Dependencies all met for dep_context=non-requeueable deps ti=<TaskInstance: batch_ingestion_dag.validate_data manual__2025-09-18T03:51:46.660947+00:00 [queued]>
[2025-09-18T04:17:59.449+0000] {taskinstance.py:1957} INFO - Dependencies all met for dep_context=requeueable deps ti=<TaskInstance: batch_ingestion_dag.validate_data manual__2025-09-18T03:51:46.660947+00:00 [queued]>
[2025-09-18T04:17:59.449+0000] {taskinstance.py:2171} INFO - Starting attempt 1 of 2
[2025-09-18T04:17:59.460+0000] {taskinstance.py:2192} INFO - Executing <Task(PythonOperator): validate_data> on 2025-09-18 03:51:46.660947+00:00
[2025-09-18T04:17:59.465+0000] {standard_task_runner.py:60} INFO - Started process 383 to run task
[2025-09-18T04:17:59.468+0000] {standard_task_runner.py:87} INFO - Running: ['***', 'tasks', 'run', 'batch_ingestion_dag', 'validate_data', 'manual__2025-09-18T03:51:46.660947+00:00', '--job-id', '6', '--raw', '--subdir', 'DAGS_FOLDER/batch_ingestion_dag.py', '--cfg-path', '/tmp/tmpzdjmthb4']
[2025-09-18T04:17:59.470+0000] {standard_task_runner.py:88} INFO - Job 6: Subtask validate_data
[2025-09-18T04:17:59.516+0000] {task_command.py:423} INFO - Running <TaskInstance: batch_ingestion_dag.validate_data manual__2025-09-18T03:51:46.660947+00:00 [running]> on host 92aeae541ff6
[2025-09-18T04:17:59.579+0000] {taskinstance.py:2481} INFO - Exporting env vars: AIRFLOW_CTX_DAG_OWNER='***' AIRFLOW_CTX_DAG_ID='batch_ingestion_dag' AIRFLOW_CTX_TASK_ID='validate_data' AIRFLOW_CTX_EXECUTION_DATE='2025-09-18T03:51:46.660947+00:00' AIRFLOW_CTX_TRY_NUMBER='1' AIRFLOW_CTX_DAG_RUN_ID='manual__2025-09-18T03:51:46.660947+00:00'
[2025-09-18T04:17:59.580+0000] {batch_ingestion_dag.py:52} INFO - Running Great Expectations validation on /tmp/orders.csv...
[2025-09-18T04:17:59.591+0000] {batch_ingestion_dag.py:73} ERROR - Failed to validate data with Great Expectations: module 'great_expectations' has no attribute 'from_pandas'
[2025-09-18T04:17:59.591+0000] {taskinstance.py:2699} ERROR - Task failed with exception
Traceback (most recent call last):
  File "/home/airflow/.local/lib/python3.9/site-packages/airflow/models/taskinstance.py", line 433, in _execute_task
    result = execute_callable(context=context, **execute_callable_kwargs)
  File "/home/airflow/.local/lib/python3.9/site-packages/airflow/operators/python.py", line 199, in execute
    return_value = self.execute_callable()
  File "/home/airflow/.local/lib/python3.9/site-packages/airflow/operators/python.py", line 216, in execute_callable
    return self.python_callable(*self.op_args, **self.op_kwargs)
  File "/opt/airflow/dags/batch_ingestion_dag.py", line 55, in validate_data_with_ge
    ge_df = ge.from_pandas(df)
AttributeError: module 'great_expectations' has no attribute 'from_pandas'
[2025-09-18T04:17:59.599+0000] {taskinstance.py:1138} INFO - Marking task as UP_FOR_RETRY. dag_id=batch_ingestion_dag, task_id=validate_data, execution_date=20250918T035146, start_date=20250918T041759, end_date=20250918T041759
[2025-09-18T04:17:59.608+0000] {standard_task_runner.py:107} ERROR - Failed to execute job 6 for task validate_data (module 'great_expectations' has no attribute 'from_pandas'; 383)
[2025-09-18T04:17:59.641+0000] {local_task_job_runner.py:234} INFO - Task exited with return code 1
[2025-09-18T04:17:59.673+0000] {taskinstance.py:3281} INFO - 0 downstream tasks scheduled from follow-on schedule check
