[2025-09-18T05:52:38.468+0000] {taskinstance.py:1957} INFO - Dependencies all met for dep_context=non-requeueable deps ti=<TaskInstance: batch_ingestion_dag.validate_data manual__2025-09-18T05:52:31.478875+00:00 [queued]>
[2025-09-18T05:52:38.476+0000] {taskinstance.py:1957} INFO - Dependencies all met for dep_context=requeueable deps ti=<TaskInstance: batch_ingestion_dag.validate_data manual__2025-09-18T05:52:31.478875+00:00 [queued]>
[2025-09-18T05:52:38.476+0000] {taskinstance.py:2171} INFO - Starting attempt 1 of 2
[2025-09-18T05:52:38.487+0000] {taskinstance.py:2192} INFO - Executing <Task(PythonOperator): validate_data> on 2025-09-18 05:52:31.478875+00:00
[2025-09-18T05:52:38.494+0000] {standard_task_runner.py:60} INFO - Started process 204 to run task
[2025-09-18T05:52:38.497+0000] {standard_task_runner.py:87} INFO - Running: ['***', 'tasks', 'run', 'batch_ingestion_dag', 'validate_data', 'manual__2025-09-18T05:52:31.478875+00:00', '--job-id', '3', '--raw', '--subdir', 'DAGS_FOLDER/batch_ingestion_dag.py', '--cfg-path', '/tmp/tmpehmx5ghs']
[2025-09-18T05:52:38.499+0000] {standard_task_runner.py:88} INFO - Job 3: Subtask validate_data
[2025-09-18T05:52:38.546+0000] {task_command.py:423} INFO - Running <TaskInstance: batch_ingestion_dag.validate_data manual__2025-09-18T05:52:31.478875+00:00 [running]> on host 2cae3ee16b76
[2025-09-18T05:52:38.613+0000] {taskinstance.py:2481} INFO - Exporting env vars: AIRFLOW_CTX_DAG_OWNER='***' AIRFLOW_CTX_DAG_ID='batch_ingestion_dag' AIRFLOW_CTX_TASK_ID='validate_data' AIRFLOW_CTX_EXECUTION_DATE='2025-09-18T05:52:31.478875+00:00' AIRFLOW_CTX_TRY_NUMBER='1' AIRFLOW_CTX_DAG_RUN_ID='manual__2025-09-18T05:52:31.478875+00:00'
[2025-09-18T05:52:38.614+0000] {batch_ingestion_dag.py:45} INFO - Running Great Expectations validation...
[2025-09-18T05:52:38.685+0000] {context_factory.py:398} INFO - Could not find local file-backed GX project
[2025-09-18T05:52:38.686+0000] {base.py:1510} INFO - Created temporary directory '/tmp/tmp1h7qo0e9' for ephemeral docs site
[2025-09-18T05:52:38.687+0000] {config.py:191} INFO - Loading 'datasources' ->
[]
[2025-09-18T05:52:38.698+0000] {batch_ingestion_dag.py:92} ERROR - Failed to validate data with Great Expectations: 'EphemeralDataContext' object has no attribute 'sources'
[2025-09-18T05:52:38.698+0000] {taskinstance.py:2699} ERROR - Task failed with exception
Traceback (most recent call last):
  File "/home/airflow/.local/lib/python3.9/site-packages/airflow/models/taskinstance.py", line 433, in _execute_task
    result = execute_callable(context=context, **execute_callable_kwargs)
  File "/home/airflow/.local/lib/python3.9/site-packages/airflow/operators/python.py", line 199, in execute
    return_value = self.execute_callable()
  File "/home/airflow/.local/lib/python3.9/site-packages/airflow/operators/python.py", line 216, in execute_callable
    return self.python_callable(*self.op_args, **self.op_kwargs)
  File "/opt/airflow/dags/batch_ingestion_dag.py", line 56, in validate_data_with_ge
    datasource = context.sources.add_pandas(name="orders_source")
AttributeError: 'EphemeralDataContext' object has no attribute 'sources'
[2025-09-18T05:52:38.710+0000] {taskinstance.py:1138} INFO - Marking task as UP_FOR_RETRY. dag_id=batch_ingestion_dag, task_id=validate_data, execution_date=20250918T055231, start_date=20250918T055238, end_date=20250918T055238
[2025-09-18T05:52:38.719+0000] {standard_task_runner.py:107} ERROR - Failed to execute job 3 for task validate_data ('EphemeralDataContext' object has no attribute 'sources'; 204)
[2025-09-18T05:52:38.749+0000] {local_task_job_runner.py:234} INFO - Task exited with return code 1
[2025-09-18T05:52:38.774+0000] {taskinstance.py:3281} INFO - 0 downstream tasks scheduled from follow-on schedule check
