[2025-09-16T08:56:17.198+0000] {taskinstance.py:1957} INFO - Dependencies all met for dep_context=non-requeueable deps ti=<TaskInstance: batch_ingestion_dag.extract_mysql manual__2025-09-16T08:51:07.571827+00:00 [queued]>
[2025-09-16T08:56:17.209+0000] {taskinstance.py:1957} INFO - Dependencies all met for dep_context=requeueable deps ti=<TaskInstance: batch_ingestion_dag.extract_mysql manual__2025-09-16T08:51:07.571827+00:00 [queued]>
[2025-09-16T08:56:17.210+0000] {taskinstance.py:2171} INFO - Starting attempt 2 of 2
[2025-09-16T08:56:17.227+0000] {taskinstance.py:2192} INFO - Executing <Task(PythonOperator): extract_mysql> on 2025-09-16 08:51:07.571827+00:00
[2025-09-16T08:56:17.236+0000] {standard_task_runner.py:60} INFO - Started process 442 to run task
[2025-09-16T08:56:17.241+0000] {standard_task_runner.py:87} INFO - Running: ['***', 'tasks', 'run', 'batch_ingestion_dag', 'extract_mysql', 'manual__2025-09-16T08:51:07.571827+00:00', '--job-id', '4', '--raw', '--subdir', 'DAGS_FOLDER/batch_ingestion_dag.py', '--cfg-path', '/tmp/tmpma7we2ec']
[2025-09-16T08:56:17.246+0000] {standard_task_runner.py:88} INFO - Job 4: Subtask extract_mysql
[2025-09-16T08:56:17.321+0000] {task_command.py:423} INFO - Running <TaskInstance: batch_ingestion_dag.extract_mysql manual__2025-09-16T08:51:07.571827+00:00 [running]> on host cc5c8a275d06
[2025-09-16T08:56:17.429+0000] {taskinstance.py:2481} INFO - Exporting env vars: AIRFLOW_CTX_DAG_OWNER='***' AIRFLOW_CTX_DAG_ID='batch_ingestion_dag' AIRFLOW_CTX_TASK_ID='extract_mysql' AIRFLOW_CTX_EXECUTION_DATE='2025-09-16T08:51:07.571827+00:00' AIRFLOW_CTX_TRY_NUMBER='2' AIRFLOW_CTX_DAG_RUN_ID='manual__2025-09-16T08:51:07.571827+00:00'
[2025-09-16T08:56:17.430+0000] {batch_ingestion_dag.py:29} INFO - Starting extraction from MySQL...
[2025-09-16T08:56:17.446+0000] {base.py:83} INFO - Using connection ID '***_db' for task execution.
[2025-09-16T08:56:17.457+0000] {batch_ingestion_dag.py:38} ERROR - Failed to extract data from MySQL: (1045, "Access denied for user 'root'@'172.20.0.8' (using password: NO)")
[2025-09-16T08:56:17.458+0000] {taskinstance.py:2699} ERROR - Task failed with exception
Traceback (most recent call last):
  File "/home/airflow/.local/lib/python3.9/site-packages/airflow/models/taskinstance.py", line 433, in _execute_task
    result = execute_callable(context=context, **execute_callable_kwargs)
  File "/home/airflow/.local/lib/python3.9/site-packages/airflow/operators/python.py", line 199, in execute
    return_value = self.execute_callable()
  File "/home/airflow/.local/lib/python3.9/site-packages/airflow/operators/python.py", line 216, in execute_callable
    return self.python_callable(*self.op_args, **self.op_kwargs)
  File "/opt/airflow/dags/batch_ingestion_dag.py", line 32, in extract_data_from_mysql
    df = mysql_hook.get_pandas_df("SELECT * FROM orders;")
  File "/home/airflow/.local/lib/python3.9/site-packages/airflow/providers/common/sql/hooks/sql.py", line 214, in get_pandas_df
    with closing(self.get_conn()) as conn:
  File "/home/airflow/.local/lib/python3.9/site-packages/airflow/providers/mysql/hooks/mysql.py", line 195, in get_conn
    return MySQLdb.connect(**conn_config)
  File "/home/airflow/.local/lib/python3.9/site-packages/MySQLdb/__init__.py", line 121, in Connect
    return Connection(*args, **kwargs)
  File "/home/airflow/.local/lib/python3.9/site-packages/MySQLdb/connections.py", line 193, in __init__
    super().__init__(*args, **kwargs2)
MySQLdb.OperationalError: (1045, "Access denied for user 'root'@'172.20.0.8' (using password: NO)")
[2025-09-16T08:56:17.472+0000] {taskinstance.py:1138} INFO - Marking task as FAILED. dag_id=batch_ingestion_dag, task_id=extract_mysql, execution_date=20250916T085107, start_date=20250916T085617, end_date=20250916T085617
[2025-09-16T08:56:17.485+0000] {standard_task_runner.py:107} ERROR - Failed to execute job 4 for task extract_mysql ((1045, "Access denied for user 'root'@'172.20.0.8' (using password: NO)"); 442)
[2025-09-16T08:56:17.535+0000] {local_task_job_runner.py:234} INFO - Task exited with return code 1
[2025-09-16T08:56:17.566+0000] {taskinstance.py:3281} INFO - 0 downstream tasks scheduled from follow-on schedule check
