[2025-09-18T03:56:51.931+0000] {taskinstance.py:1957} INFO - Dependencies all met for dep_context=non-requeueable deps ti=<TaskInstance: batch_ingestion_dag.extract_mysql manual__2025-09-18T03:51:46.660947+00:00 [queued]>
[2025-09-18T03:56:51.938+0000] {taskinstance.py:1957} INFO - Dependencies all met for dep_context=requeueable deps ti=<TaskInstance: batch_ingestion_dag.extract_mysql manual__2025-09-18T03:51:46.660947+00:00 [queued]>
[2025-09-18T03:56:51.938+0000] {taskinstance.py:2171} INFO - Starting attempt 2 of 2
[2025-09-18T03:56:51.947+0000] {taskinstance.py:2192} INFO - Executing <Task(PythonOperator): extract_mysql> on 2025-09-18 03:51:46.660947+00:00
[2025-09-18T03:56:51.952+0000] {standard_task_runner.py:60} INFO - Started process 726 to run task
[2025-09-18T03:56:51.957+0000] {standard_task_runner.py:87} INFO - Running: ['***', 'tasks', 'run', 'batch_ingestion_dag', 'extract_mysql', 'manual__2025-09-18T03:51:46.660947+00:00', '--job-id', '3', '--raw', '--subdir', 'DAGS_FOLDER/batch_ingestion_dag.py', '--cfg-path', '/tmp/tmp1bi8j0i8']
[2025-09-18T03:56:51.959+0000] {standard_task_runner.py:88} INFO - Job 3: Subtask extract_mysql
[2025-09-18T03:56:52.013+0000] {task_command.py:423} INFO - Running <TaskInstance: batch_ingestion_dag.extract_mysql manual__2025-09-18T03:51:46.660947+00:00 [running]> on host a38be288a850
[2025-09-18T03:56:52.081+0000] {taskinstance.py:2481} INFO - Exporting env vars: AIRFLOW_CTX_DAG_OWNER='***' AIRFLOW_CTX_DAG_ID='batch_ingestion_dag' AIRFLOW_CTX_TASK_ID='extract_mysql' AIRFLOW_CTX_EXECUTION_DATE='2025-09-18T03:51:46.660947+00:00' AIRFLOW_CTX_TRY_NUMBER='2' AIRFLOW_CTX_DAG_RUN_ID='manual__2025-09-18T03:51:46.660947+00:00'
[2025-09-18T03:56:52.083+0000] {batch_ingestion_dag.py:29} INFO - Starting extraction from MySQL...
[2025-09-18T03:56:52.090+0000] {base.py:83} INFO - Using connection ID '***_db' for task execution.
[2025-09-18T03:56:52.098+0000] {batch_ingestion_dag.py:38} ERROR - Failed to extract data from MySQL: (1045, "Access denied for user 'root'@'172.20.0.9' (using password: NO)")
[2025-09-18T03:56:52.098+0000] {taskinstance.py:2699} ERROR - Task failed with exception
Traceback (most recent call last):
  File "/home/airflow/.local/lib/python3.9/site-packages/airflow/models/taskinstance.py", line 433, in _execute_task
    result = execute_callable(context=context, **execute_callable_kwargs)
  File "/home/airflow/.local/lib/python3.9/site-packages/airflow/operators/python.py", line 199, in execute
    return_value = self.execute_callable()
  File "/home/airflow/.local/lib/python3.9/site-packages/airflow/operators/python.py", line 216, in execute_callable
    return self.python_callable(*self.op_args, **self.op_kwargs)
  File "/opt/airflow/dags/batch_ingestion_dag.py", line 32, in extract_data_from_mysql
    df = mysql_hook.get_pandas_df("SELECT * FROM orders;")
  File "/home/airflow/.local/lib/python3.9/site-packages/airflow/providers/common/sql/hooks/sql.py", line 214, in get_pandas_df
    with closing(self.get_conn()) as conn:
  File "/home/airflow/.local/lib/python3.9/site-packages/airflow/providers/mysql/hooks/mysql.py", line 195, in get_conn
    return MySQLdb.connect(**conn_config)
  File "/home/airflow/.local/lib/python3.9/site-packages/MySQLdb/__init__.py", line 121, in Connect
    return Connection(*args, **kwargs)
  File "/home/airflow/.local/lib/python3.9/site-packages/MySQLdb/connections.py", line 193, in __init__
    super().__init__(*args, **kwargs2)
MySQLdb.OperationalError: (1045, "Access denied for user 'root'@'172.20.0.9' (using password: NO)")
[2025-09-18T03:56:52.108+0000] {taskinstance.py:1138} INFO - Marking task as FAILED. dag_id=batch_ingestion_dag, task_id=extract_mysql, execution_date=20250918T035146, start_date=20250918T035651, end_date=20250918T035652
[2025-09-18T03:56:52.116+0000] {standard_task_runner.py:107} ERROR - Failed to execute job 3 for task extract_mysql ((1045, "Access denied for user 'root'@'172.20.0.9' (using password: NO)"); 726)
[2025-09-18T03:56:52.130+0000] {local_task_job_runner.py:234} INFO - Task exited with return code 1
[2025-09-18T03:56:52.147+0000] {taskinstance.py:3281} INFO - 0 downstream tasks scheduled from follow-on schedule check
